[2025-09-04T00:39:32.625+0000] {local_task_job_runner.py:120} INFO - ::group::Pre task execution logs
[2025-09-04T00:39:32.680+0000] {taskinstance.py:2076} INFO - Dependencies all met for dep_context=non-requeueable deps ti=<TaskInstance: banvic_pipeline.load_dw manual__2025-09-04T00:34:15.908726+00:00 [queued]>
[2025-09-04T00:39:32.687+0000] {taskinstance.py:2076} INFO - Dependencies all met for dep_context=requeueable deps ti=<TaskInstance: banvic_pipeline.load_dw manual__2025-09-04T00:34:15.908726+00:00 [queued]>
[2025-09-04T00:39:32.688+0000] {taskinstance.py:2306} INFO - Starting attempt 1 of 2
[2025-09-04T00:39:32.701+0000] {taskinstance.py:2330} INFO - Executing <Task(BashOperator): load_dw> on 2025-09-04 00:34:15.908726+00:00
[2025-09-04T00:39:32.706+0000] {standard_task_runner.py:64} INFO - Started process 305 to run task
[2025-09-04T00:39:32.712+0000] {standard_task_runner.py:90} INFO - Running: ['airflow', 'tasks', 'run', 'banvic_pipeline', 'load_dw', 'manual__2025-09-04T00:34:15.908726+00:00', '--job-id', '52', '--raw', '--subdir', 'DAGS_FOLDER/banvic_pipeline.py', '--cfg-path', '/tmp/tmpmygszx_m']
[2025-09-04T00:39:32.714+0000] {standard_task_runner.py:91} INFO - Job 52: Subtask load_dw
[2025-09-04T00:39:32.850+0000] {task_command.py:426} INFO - Running <TaskInstance: banvic_pipeline.load_dw manual__2025-09-04T00:34:15.908726+00:00 [running]> on host 8ecc11fed1c2
[2025-09-04T00:39:33.088+0000] {taskinstance.py:2648} INFO - Exporting env vars: AIRFLOW_CTX_DAG_OWNER='lucas' AIRFLOW_CTX_DAG_ID='banvic_pipeline' AIRFLOW_CTX_TASK_ID='load_dw' AIRFLOW_CTX_EXECUTION_DATE='2025-09-04T00:34:15.908726+00:00' AIRFLOW_CTX_TRY_NUMBER='1' AIRFLOW_CTX_DAG_RUN_ID='manual__2025-09-04T00:34:15.908726+00:00'
[2025-09-04T00:39:33.090+0000] {taskinstance.py:430} INFO - ::endgroup::
[2025-09-04T00:39:33.114+0000] {subprocess.py:63} INFO - Tmp dir root location: /tmp
[2025-09-04T00:39:33.117+0000] {subprocess.py:75} INFO - Running command: ['/usr/bin/bash', '-c', 'cd /opt/airflow/project && python scripts/load_dw.py']
[2025-09-04T00:39:33.130+0000] {subprocess.py:86} INFO - Output:
[2025-09-04T00:39:33.440+0000] {subprocess.py:93} INFO - Traceback (most recent call last):
[2025-09-04T00:39:33.442+0000] {subprocess.py:93} INFO -   File "/opt/airflow/project/scripts/load_dw.py", line 103, in <module>
[2025-09-04T00:39:33.447+0000] {subprocess.py:93} INFO -     main()
[2025-09-04T00:39:33.448+0000] {subprocess.py:93} INFO -   File "/opt/airflow/project/scripts/load_dw.py", line 63, in main
[2025-09-04T00:39:33.452+0000] {subprocess.py:93} INFO -     conn = get_dw_conn()
[2025-09-04T00:39:33.454+0000] {subprocess.py:93} INFO -   File "/opt/airflow/project/scripts/load_dw.py", line 29, in get_dw_conn
[2025-09-04T00:39:33.458+0000] {subprocess.py:93} INFO -     return psycopg2.connect(
[2025-09-04T00:39:33.461+0000] {subprocess.py:93} INFO -   File "/home/airflow/.local/lib/python3.10/site-packages/psycopg2/__init__.py", line 122, in connect
[2025-09-04T00:39:33.464+0000] {subprocess.py:93} INFO -     conn = _connect(dsn, connection_factory=connection_factory, **kwasync)
[2025-09-04T00:39:33.466+0000] {subprocess.py:93} INFO - psycopg2.OperationalError: connection to server at "localhost" (::1), port 56432 failed: Connection refused
[2025-09-04T00:39:33.467+0000] {subprocess.py:93} INFO - 	Is the server running on that host and accepting TCP/IP connections?
[2025-09-04T00:39:33.468+0000] {subprocess.py:93} INFO - connection to server at "localhost" (127.0.0.1), port 56432 failed: Connection refused
[2025-09-04T00:39:33.470+0000] {subprocess.py:93} INFO - 	Is the server running on that host and accepting TCP/IP connections?
[2025-09-04T00:39:33.471+0000] {subprocess.py:93} INFO - 
[2025-09-04T00:39:33.484+0000] {subprocess.py:97} INFO - Command exited with return code 1
[2025-09-04T00:39:33.488+0000] {taskinstance.py:441} INFO - ::group::Post task execution logs
[2025-09-04T00:39:33.567+0000] {taskinstance.py:2905} ERROR - Task failed with exception
Traceback (most recent call last):
  File "/home/airflow/.local/lib/python3.10/site-packages/airflow/models/taskinstance.py", line 465, in _execute_task
    result = _execute_callable(context=context, **execute_callable_kwargs)
  File "/home/airflow/.local/lib/python3.10/site-packages/airflow/models/taskinstance.py", line 432, in _execute_callable
    return execute_callable(context=context, **execute_callable_kwargs)
  File "/home/airflow/.local/lib/python3.10/site-packages/airflow/models/baseoperator.py", line 401, in wrapper
    return func(self, *args, **kwargs)
  File "/home/airflow/.local/lib/python3.10/site-packages/airflow/operators/bash.py", line 243, in execute
    raise AirflowException(
airflow.exceptions.AirflowException: Bash command failed. The command returned a non-zero exit code 1.
[2025-09-04T00:39:33.586+0000] {taskinstance.py:1206} INFO - Marking task as UP_FOR_RETRY. dag_id=banvic_pipeline, task_id=load_dw, run_id=manual__2025-09-04T00:34:15.908726+00:00, execution_date=20250904T003415, start_date=20250904T003932, end_date=20250904T003933
[2025-09-04T00:39:33.655+0000] {standard_task_runner.py:110} ERROR - Failed to execute job 52 for task load_dw (Bash command failed. The command returned a non-zero exit code 1.; 305)
[2025-09-04T00:39:33.692+0000] {local_task_job_runner.py:243} INFO - Task exited with return code 1
[2025-09-04T00:39:33.754+0000] {taskinstance.py:3503} INFO - 0 downstream tasks scheduled from follow-on schedule check
[2025-09-04T00:39:33.760+0000] {local_task_job_runner.py:222} INFO - ::endgroup::
