[2025-09-03T23:55:26.743+0000] {local_task_job_runner.py:120} INFO - ::group::Pre task execution logs
[2025-09-03T23:55:26.844+0000] {taskinstance.py:2076} INFO - Dependencies all met for dep_context=non-requeueable deps ti=<TaskInstance: banvic_pipeline.extract_postgres manual__2025-09-03T23:50:14.906018+00:00 [queued]>
[2025-09-03T23:55:26.860+0000] {taskinstance.py:2076} INFO - Dependencies all met for dep_context=requeueable deps ti=<TaskInstance: banvic_pipeline.extract_postgres manual__2025-09-03T23:50:14.906018+00:00 [queued]>
[2025-09-03T23:55:26.867+0000] {taskinstance.py:2306} INFO - Starting attempt 1 of 2
[2025-09-03T23:55:26.897+0000] {taskinstance.py:2330} INFO - Executing <Task(BashOperator): extract_postgres> on 2025-09-03 23:50:14.906018+00:00
[2025-09-03T23:55:26.910+0000] {standard_task_runner.py:64} INFO - Started process 291 to run task
[2025-09-03T23:55:26.923+0000] {standard_task_runner.py:90} INFO - Running: ['airflow', 'tasks', 'run', 'banvic_pipeline', 'extract_postgres', 'manual__2025-09-03T23:50:14.906018+00:00', '--job-id', '37', '--raw', '--subdir', 'DAGS_FOLDER/banvic_pipeline.py', '--cfg-path', '/tmp/tmpwkxfzc0s']
[2025-09-03T23:55:26.930+0000] {standard_task_runner.py:91} INFO - Job 37: Subtask extract_postgres
[2025-09-03T23:55:27.237+0000] {task_command.py:426} INFO - Running <TaskInstance: banvic_pipeline.extract_postgres manual__2025-09-03T23:50:14.906018+00:00 [running]> on host 644a78dce44d
[2025-09-03T23:55:27.739+0000] {taskinstance.py:2648} INFO - Exporting env vars: AIRFLOW_CTX_DAG_OWNER='lucas' AIRFLOW_CTX_DAG_ID='banvic_pipeline' AIRFLOW_CTX_TASK_ID='extract_postgres' AIRFLOW_CTX_EXECUTION_DATE='2025-09-03T23:50:14.906018+00:00' AIRFLOW_CTX_TRY_NUMBER='1' AIRFLOW_CTX_DAG_RUN_ID='manual__2025-09-03T23:50:14.906018+00:00'
[2025-09-03T23:55:27.741+0000] {taskinstance.py:430} INFO - ::endgroup::
[2025-09-03T23:55:27.765+0000] {subprocess.py:63} INFO - Tmp dir root location: /tmp
[2025-09-03T23:55:27.766+0000] {subprocess.py:75} INFO - Running command: ['/usr/bin/bash', '-c', 'python /opt/airflow/project/scripts/extracao_postgres/extracao_completa.py']
[2025-09-03T23:55:27.781+0000] {subprocess.py:86} INFO - Output:
[2025-09-03T23:55:29.281+0000] {subprocess.py:93} INFO - Traceback (most recent call last):
[2025-09-03T23:55:29.283+0000] {subprocess.py:93} INFO -   File "/opt/airflow/project/scripts/extracao_postgres/extracao_completa.py", line 12, in <module>
[2025-09-03T23:55:29.290+0000] {subprocess.py:93} INFO -     conn = psycopg2.connect(
[2025-09-03T23:55:29.291+0000] {subprocess.py:93} INFO -   File "/home/airflow/.local/lib/python3.10/site-packages/psycopg2/__init__.py", line 122, in connect
[2025-09-03T23:55:29.292+0000] {subprocess.py:93} INFO -     conn = _connect(dsn, connection_factory=connection_factory, **kwasync)
[2025-09-03T23:55:29.293+0000] {subprocess.py:93} INFO - psycopg2.OperationalError: connection to server at "localhost" (::1), port 55432 failed: Connection refused
[2025-09-03T23:55:29.294+0000] {subprocess.py:93} INFO - 	Is the server running on that host and accepting TCP/IP connections?
[2025-09-03T23:55:29.294+0000] {subprocess.py:93} INFO - connection to server at "localhost" (127.0.0.1), port 55432 failed: Connection refused
[2025-09-03T23:55:29.295+0000] {subprocess.py:93} INFO - 	Is the server running on that host and accepting TCP/IP connections?
[2025-09-03T23:55:29.296+0000] {subprocess.py:93} INFO - 
[2025-09-03T23:55:29.402+0000] {subprocess.py:97} INFO - Command exited with return code 1
[2025-09-03T23:55:29.405+0000] {taskinstance.py:441} INFO - ::group::Post task execution logs
[2025-09-03T23:55:29.489+0000] {taskinstance.py:2905} ERROR - Task failed with exception
Traceback (most recent call last):
  File "/home/airflow/.local/lib/python3.10/site-packages/airflow/models/taskinstance.py", line 465, in _execute_task
    result = _execute_callable(context=context, **execute_callable_kwargs)
  File "/home/airflow/.local/lib/python3.10/site-packages/airflow/models/taskinstance.py", line 432, in _execute_callable
    return execute_callable(context=context, **execute_callable_kwargs)
  File "/home/airflow/.local/lib/python3.10/site-packages/airflow/models/baseoperator.py", line 401, in wrapper
    return func(self, *args, **kwargs)
  File "/home/airflow/.local/lib/python3.10/site-packages/airflow/operators/bash.py", line 243, in execute
    raise AirflowException(
airflow.exceptions.AirflowException: Bash command failed. The command returned a non-zero exit code 1.
[2025-09-03T23:55:29.494+0000] {taskinstance.py:1206} INFO - Marking task as UP_FOR_RETRY. dag_id=banvic_pipeline, task_id=extract_postgres, run_id=manual__2025-09-03T23:50:14.906018+00:00, execution_date=20250903T235014, start_date=20250903T235526, end_date=20250903T235529
[2025-09-03T23:55:29.561+0000] {standard_task_runner.py:110} ERROR - Failed to execute job 37 for task extract_postgres (Bash command failed. The command returned a non-zero exit code 1.; 291)
[2025-09-03T23:55:29.593+0000] {local_task_job_runner.py:243} INFO - Task exited with return code 1
[2025-09-03T23:55:29.734+0000] {taskinstance.py:3503} INFO - 0 downstream tasks scheduled from follow-on schedule check
[2025-09-03T23:55:29.759+0000] {local_task_job_runner.py:222} INFO - ::endgroup::
