[2025-09-04T00:29:37.964+0000] {local_task_job_runner.py:120} INFO - ::group::Pre task execution logs
[2025-09-04T00:29:38.020+0000] {taskinstance.py:2076} INFO - Dependencies all met for dep_context=non-requeueable deps ti=<TaskInstance: banvic_pipeline.load_dw scheduled__2025-09-02T07:35:00+00:00 [queued]>
[2025-09-04T00:29:38.028+0000] {taskinstance.py:2076} INFO - Dependencies all met for dep_context=requeueable deps ti=<TaskInstance: banvic_pipeline.load_dw scheduled__2025-09-02T07:35:00+00:00 [queued]>
[2025-09-04T00:29:38.029+0000] {taskinstance.py:2306} INFO - Starting attempt 2 of 2
[2025-09-04T00:29:38.041+0000] {taskinstance.py:2330} INFO - Executing <Task(BashOperator): load_dw> on 2025-09-02 07:35:00+00:00
[2025-09-04T00:29:38.046+0000] {standard_task_runner.py:64} INFO - Started process 728 to run task
[2025-09-04T00:29:38.049+0000] {standard_task_runner.py:90} INFO - Running: ['airflow', 'tasks', 'run', 'banvic_pipeline', 'load_dw', 'scheduled__2025-09-02T07:35:00+00:00', '--job-id', '44', '--raw', '--subdir', 'DAGS_FOLDER/banvic_pipeline.py', '--cfg-path', '/tmp/tmpooppjuyz']
[2025-09-04T00:29:38.052+0000] {standard_task_runner.py:91} INFO - Job 44: Subtask load_dw
[2025-09-04T00:29:38.186+0000] {task_command.py:426} INFO - Running <TaskInstance: banvic_pipeline.load_dw scheduled__2025-09-02T07:35:00+00:00 [running]> on host 644a78dce44d
[2025-09-04T00:29:38.375+0000] {taskinstance.py:2648} INFO - Exporting env vars: AIRFLOW_CTX_DAG_OWNER='lucas' AIRFLOW_CTX_DAG_ID='banvic_pipeline' AIRFLOW_CTX_TASK_ID='load_dw' AIRFLOW_CTX_EXECUTION_DATE='2025-09-02T07:35:00+00:00' AIRFLOW_CTX_TRY_NUMBER='2' AIRFLOW_CTX_DAG_RUN_ID='scheduled__2025-09-02T07:35:00+00:00'
[2025-09-04T00:29:38.376+0000] {taskinstance.py:430} INFO - ::endgroup::
[2025-09-04T00:29:38.386+0000] {subprocess.py:63} INFO - Tmp dir root location: /tmp
[2025-09-04T00:29:38.388+0000] {subprocess.py:75} INFO - Running command: ['/usr/bin/bash', '-c', 'cd /opt/airflow/project && python scripts/load_dw.py']
[2025-09-04T00:29:38.396+0000] {subprocess.py:86} INFO - Output:
[2025-09-04T00:29:38.547+0000] {subprocess.py:93} INFO - Traceback (most recent call last):
[2025-09-04T00:29:38.547+0000] {subprocess.py:93} INFO -   File "/opt/airflow/project/scripts/load_dw.py", line 103, in <module>
[2025-09-04T00:29:38.548+0000] {subprocess.py:93} INFO -     main()
[2025-09-04T00:29:38.549+0000] {subprocess.py:93} INFO -   File "/opt/airflow/project/scripts/load_dw.py", line 63, in main
[2025-09-04T00:29:38.550+0000] {subprocess.py:93} INFO -     conn = get_dw_conn()
[2025-09-04T00:29:38.550+0000] {subprocess.py:93} INFO -   File "/opt/airflow/project/scripts/load_dw.py", line 29, in get_dw_conn
[2025-09-04T00:29:38.551+0000] {subprocess.py:93} INFO -     return psycopg2.connect(
[2025-09-04T00:29:38.551+0000] {subprocess.py:93} INFO -   File "/home/airflow/.local/lib/python3.10/site-packages/psycopg2/__init__.py", line 122, in connect
[2025-09-04T00:29:38.552+0000] {subprocess.py:93} INFO -     conn = _connect(dsn, connection_factory=connection_factory, **kwasync)
[2025-09-04T00:29:38.552+0000] {subprocess.py:93} INFO - psycopg2.OperationalError: connection to server at "localhost" (::1), port 56432 failed: Connection refused
[2025-09-04T00:29:38.552+0000] {subprocess.py:93} INFO - 	Is the server running on that host and accepting TCP/IP connections?
[2025-09-04T00:29:38.552+0000] {subprocess.py:93} INFO - connection to server at "localhost" (127.0.0.1), port 56432 failed: Connection refused
[2025-09-04T00:29:38.552+0000] {subprocess.py:93} INFO - 	Is the server running on that host and accepting TCP/IP connections?
[2025-09-04T00:29:38.553+0000] {subprocess.py:93} INFO - 
[2025-09-04T00:29:38.557+0000] {subprocess.py:97} INFO - Command exited with return code 1
[2025-09-04T00:29:38.558+0000] {taskinstance.py:441} INFO - ::group::Post task execution logs
[2025-09-04T00:29:38.596+0000] {taskinstance.py:2905} ERROR - Task failed with exception
Traceback (most recent call last):
  File "/home/airflow/.local/lib/python3.10/site-packages/airflow/models/taskinstance.py", line 465, in _execute_task
    result = _execute_callable(context=context, **execute_callable_kwargs)
  File "/home/airflow/.local/lib/python3.10/site-packages/airflow/models/taskinstance.py", line 432, in _execute_callable
    return execute_callable(context=context, **execute_callable_kwargs)
  File "/home/airflow/.local/lib/python3.10/site-packages/airflow/models/baseoperator.py", line 401, in wrapper
    return func(self, *args, **kwargs)
  File "/home/airflow/.local/lib/python3.10/site-packages/airflow/operators/bash.py", line 243, in execute
    raise AirflowException(
airflow.exceptions.AirflowException: Bash command failed. The command returned a non-zero exit code 1.
[2025-09-04T00:29:38.599+0000] {taskinstance.py:1206} INFO - Marking task as FAILED. dag_id=banvic_pipeline, task_id=load_dw, run_id=scheduled__2025-09-02T07:35:00+00:00, execution_date=20250902T073500, start_date=20250904T002938, end_date=20250904T002938
[2025-09-04T00:29:38.630+0000] {standard_task_runner.py:110} ERROR - Failed to execute job 44 for task load_dw (Bash command failed. The command returned a non-zero exit code 1.; 728)
[2025-09-04T00:29:38.665+0000] {local_task_job_runner.py:243} INFO - Task exited with return code 1
[2025-09-04T00:29:38.727+0000] {taskinstance.py:3503} INFO - 0 downstream tasks scheduled from follow-on schedule check
[2025-09-04T00:29:38.730+0000] {local_task_job_runner.py:222} INFO - ::endgroup::
[2025-09-04T00:39:25.459+0000] {local_task_job_runner.py:120} INFO - ::group::Pre task execution logs
[2025-09-04T00:39:25.534+0000] {taskinstance.py:2076} INFO - Dependencies all met for dep_context=non-requeueable deps ti=<TaskInstance: banvic_pipeline.load_dw scheduled__2025-09-02T07:35:00+00:00 [queued]>
[2025-09-04T00:39:25.561+0000] {taskinstance.py:2076} INFO - Dependencies all met for dep_context=requeueable deps ti=<TaskInstance: banvic_pipeline.load_dw scheduled__2025-09-02T07:35:00+00:00 [queued]>
[2025-09-04T00:39:25.561+0000] {taskinstance.py:2306} INFO - Starting attempt 2 of 2
[2025-09-04T00:39:25.578+0000] {taskinstance.py:2330} INFO - Executing <Task(BashOperator): load_dw> on 2025-09-02 07:35:00+00:00
[2025-09-04T00:39:25.583+0000] {standard_task_runner.py:64} INFO - Started process 272 to run task
[2025-09-04T00:39:25.586+0000] {standard_task_runner.py:90} INFO - Running: ['airflow', 'tasks', 'run', 'banvic_pipeline', 'load_dw', 'scheduled__2025-09-02T07:35:00+00:00', '--job-id', '49', '--raw', '--subdir', 'DAGS_FOLDER/banvic_pipeline.py', '--cfg-path', '/tmp/tmp_6sgikf7']
[2025-09-04T00:39:25.591+0000] {standard_task_runner.py:91} INFO - Job 49: Subtask load_dw
[2025-09-04T00:39:25.918+0000] {task_command.py:426} INFO - Running <TaskInstance: banvic_pipeline.load_dw scheduled__2025-09-02T07:35:00+00:00 [running]> on host 8ecc11fed1c2
[2025-09-04T00:39:26.149+0000] {taskinstance.py:2648} INFO - Exporting env vars: AIRFLOW_CTX_DAG_OWNER='lucas' AIRFLOW_CTX_DAG_ID='banvic_pipeline' AIRFLOW_CTX_TASK_ID='load_dw' AIRFLOW_CTX_EXECUTION_DATE='2025-09-02T07:35:00+00:00' AIRFLOW_CTX_TRY_NUMBER='2' AIRFLOW_CTX_DAG_RUN_ID='scheduled__2025-09-02T07:35:00+00:00'
[2025-09-04T00:39:26.150+0000] {taskinstance.py:430} INFO - ::endgroup::
[2025-09-04T00:39:26.167+0000] {subprocess.py:63} INFO - Tmp dir root location: /tmp
[2025-09-04T00:39:26.171+0000] {subprocess.py:75} INFO - Running command: ['/usr/bin/bash', '-c', 'cd /opt/airflow/project && python scripts/load_dw.py']
[2025-09-04T00:39:26.182+0000] {subprocess.py:86} INFO - Output:
[2025-09-04T00:39:26.459+0000] {subprocess.py:93} INFO - Traceback (most recent call last):
[2025-09-04T00:39:26.460+0000] {subprocess.py:93} INFO -   File "/opt/airflow/project/scripts/load_dw.py", line 103, in <module>
[2025-09-04T00:39:26.462+0000] {subprocess.py:93} INFO -     main()
[2025-09-04T00:39:26.462+0000] {subprocess.py:93} INFO -   File "/opt/airflow/project/scripts/load_dw.py", line 63, in main
[2025-09-04T00:39:26.464+0000] {subprocess.py:93} INFO -     conn = get_dw_conn()
[2025-09-04T00:39:26.465+0000] {subprocess.py:93} INFO -   File "/opt/airflow/project/scripts/load_dw.py", line 29, in get_dw_conn
[2025-09-04T00:39:26.466+0000] {subprocess.py:93} INFO -     return psycopg2.connect(
[2025-09-04T00:39:26.467+0000] {subprocess.py:93} INFO -   File "/home/airflow/.local/lib/python3.10/site-packages/psycopg2/__init__.py", line 122, in connect
[2025-09-04T00:39:26.467+0000] {subprocess.py:93} INFO -     conn = _connect(dsn, connection_factory=connection_factory, **kwasync)
[2025-09-04T00:39:26.468+0000] {subprocess.py:93} INFO - psycopg2.OperationalError: connection to server at "localhost" (::1), port 56432 failed: Connection refused
[2025-09-04T00:39:26.468+0000] {subprocess.py:93} INFO - 	Is the server running on that host and accepting TCP/IP connections?
[2025-09-04T00:39:26.469+0000] {subprocess.py:93} INFO - connection to server at "localhost" (127.0.0.1), port 56432 failed: Connection refused
[2025-09-04T00:39:26.469+0000] {subprocess.py:93} INFO - 	Is the server running on that host and accepting TCP/IP connections?
[2025-09-04T00:39:26.470+0000] {subprocess.py:93} INFO - 
[2025-09-04T00:39:26.473+0000] {subprocess.py:97} INFO - Command exited with return code 1
[2025-09-04T00:39:26.474+0000] {taskinstance.py:441} INFO - ::group::Post task execution logs
[2025-09-04T00:39:26.504+0000] {taskinstance.py:2905} ERROR - Task failed with exception
Traceback (most recent call last):
  File "/home/airflow/.local/lib/python3.10/site-packages/airflow/models/taskinstance.py", line 465, in _execute_task
    result = _execute_callable(context=context, **execute_callable_kwargs)
  File "/home/airflow/.local/lib/python3.10/site-packages/airflow/models/taskinstance.py", line 432, in _execute_callable
    return execute_callable(context=context, **execute_callable_kwargs)
  File "/home/airflow/.local/lib/python3.10/site-packages/airflow/models/baseoperator.py", line 401, in wrapper
    return func(self, *args, **kwargs)
  File "/home/airflow/.local/lib/python3.10/site-packages/airflow/operators/bash.py", line 243, in execute
    raise AirflowException(
airflow.exceptions.AirflowException: Bash command failed. The command returned a non-zero exit code 1.
[2025-09-04T00:39:26.507+0000] {taskinstance.py:1206} INFO - Marking task as FAILED. dag_id=banvic_pipeline, task_id=load_dw, run_id=scheduled__2025-09-02T07:35:00+00:00, execution_date=20250902T073500, start_date=20250904T003925, end_date=20250904T003926
[2025-09-04T00:39:26.539+0000] {standard_task_runner.py:110} ERROR - Failed to execute job 49 for task load_dw (Bash command failed. The command returned a non-zero exit code 1.; 272)
[2025-09-04T00:39:26.569+0000] {local_task_job_runner.py:243} INFO - Task exited with return code 1
[2025-09-04T00:39:26.625+0000] {taskinstance.py:3503} INFO - 0 downstream tasks scheduled from follow-on schedule check
[2025-09-04T00:39:26.630+0000] {local_task_job_runner.py:222} INFO - ::endgroup::
