[2025-09-04T00:24:36.538+0000] {local_task_job_runner.py:120} INFO - ::group::Pre task execution logs
[2025-09-04T00:24:36.608+0000] {taskinstance.py:2076} INFO - Dependencies all met for dep_context=non-requeueable deps ti=<TaskInstance: banvic_pipeline.load_dw scheduled__2025-09-02T07:35:00+00:00 [queued]>
[2025-09-04T00:24:36.620+0000] {taskinstance.py:2076} INFO - Dependencies all met for dep_context=requeueable deps ti=<TaskInstance: banvic_pipeline.load_dw scheduled__2025-09-02T07:35:00+00:00 [queued]>
[2025-09-04T00:24:36.621+0000] {taskinstance.py:2306} INFO - Starting attempt 1 of 2
[2025-09-04T00:24:36.638+0000] {taskinstance.py:2330} INFO - Executing <Task(BashOperator): load_dw> on 2025-09-02 07:35:00+00:00
[2025-09-04T00:24:36.643+0000] {standard_task_runner.py:64} INFO - Started process 675 to run task
[2025-09-04T00:24:36.648+0000] {standard_task_runner.py:90} INFO - Running: ['airflow', 'tasks', 'run', 'banvic_pipeline', 'load_dw', 'scheduled__2025-09-02T07:35:00+00:00', '--job-id', '43', '--raw', '--subdir', 'DAGS_FOLDER/banvic_pipeline.py', '--cfg-path', '/tmp/tmpq2_qnjoz']
[2025-09-04T00:24:36.654+0000] {standard_task_runner.py:91} INFO - Job 43: Subtask load_dw
[2025-09-04T00:24:36.802+0000] {task_command.py:426} INFO - Running <TaskInstance: banvic_pipeline.load_dw scheduled__2025-09-02T07:35:00+00:00 [running]> on host 644a78dce44d
[2025-09-04T00:24:37.025+0000] {taskinstance.py:2648} INFO - Exporting env vars: AIRFLOW_CTX_DAG_OWNER='lucas' AIRFLOW_CTX_DAG_ID='banvic_pipeline' AIRFLOW_CTX_TASK_ID='load_dw' AIRFLOW_CTX_EXECUTION_DATE='2025-09-02T07:35:00+00:00' AIRFLOW_CTX_TRY_NUMBER='1' AIRFLOW_CTX_DAG_RUN_ID='scheduled__2025-09-02T07:35:00+00:00'
[2025-09-04T00:24:37.026+0000] {taskinstance.py:430} INFO - ::endgroup::
[2025-09-04T00:24:37.044+0000] {subprocess.py:63} INFO - Tmp dir root location: /tmp
[2025-09-04T00:24:37.049+0000] {subprocess.py:75} INFO - Running command: ['/usr/bin/bash', '-c', 'cd /opt/airflow/project && python scripts/load_dw.py']
[2025-09-04T00:24:37.077+0000] {subprocess.py:86} INFO - Output:
[2025-09-04T00:24:37.461+0000] {subprocess.py:93} INFO - Traceback (most recent call last):
[2025-09-04T00:24:37.462+0000] {subprocess.py:93} INFO -   File "/opt/airflow/project/scripts/load_dw.py", line 103, in <module>
[2025-09-04T00:24:37.468+0000] {subprocess.py:93} INFO -     main()
[2025-09-04T00:24:37.469+0000] {subprocess.py:93} INFO -   File "/opt/airflow/project/scripts/load_dw.py", line 63, in main
[2025-09-04T00:24:37.471+0000] {subprocess.py:93} INFO -     conn = get_dw_conn()
[2025-09-04T00:24:37.472+0000] {subprocess.py:93} INFO -   File "/opt/airflow/project/scripts/load_dw.py", line 29, in get_dw_conn
[2025-09-04T00:24:37.474+0000] {subprocess.py:93} INFO -     return psycopg2.connect(
[2025-09-04T00:24:37.475+0000] {subprocess.py:93} INFO -   File "/home/airflow/.local/lib/python3.10/site-packages/psycopg2/__init__.py", line 122, in connect
[2025-09-04T00:24:37.476+0000] {subprocess.py:93} INFO -     conn = _connect(dsn, connection_factory=connection_factory, **kwasync)
[2025-09-04T00:24:37.476+0000] {subprocess.py:93} INFO - psycopg2.OperationalError: connection to server at "localhost" (::1), port 56432 failed: Connection refused
[2025-09-04T00:24:37.477+0000] {subprocess.py:93} INFO - 	Is the server running on that host and accepting TCP/IP connections?
[2025-09-04T00:24:37.477+0000] {subprocess.py:93} INFO - connection to server at "localhost" (127.0.0.1), port 56432 failed: Connection refused
[2025-09-04T00:24:37.478+0000] {subprocess.py:93} INFO - 	Is the server running on that host and accepting TCP/IP connections?
[2025-09-04T00:24:37.478+0000] {subprocess.py:93} INFO - 
[2025-09-04T00:24:37.481+0000] {subprocess.py:97} INFO - Command exited with return code 1
[2025-09-04T00:24:37.482+0000] {taskinstance.py:441} INFO - ::group::Post task execution logs
[2025-09-04T00:24:37.517+0000] {taskinstance.py:2905} ERROR - Task failed with exception
Traceback (most recent call last):
  File "/home/airflow/.local/lib/python3.10/site-packages/airflow/models/taskinstance.py", line 465, in _execute_task
    result = _execute_callable(context=context, **execute_callable_kwargs)
  File "/home/airflow/.local/lib/python3.10/site-packages/airflow/models/taskinstance.py", line 432, in _execute_callable
    return execute_callable(context=context, **execute_callable_kwargs)
  File "/home/airflow/.local/lib/python3.10/site-packages/airflow/models/baseoperator.py", line 401, in wrapper
    return func(self, *args, **kwargs)
  File "/home/airflow/.local/lib/python3.10/site-packages/airflow/operators/bash.py", line 243, in execute
    raise AirflowException(
airflow.exceptions.AirflowException: Bash command failed. The command returned a non-zero exit code 1.
[2025-09-04T00:24:37.522+0000] {taskinstance.py:1206} INFO - Marking task as UP_FOR_RETRY. dag_id=banvic_pipeline, task_id=load_dw, run_id=scheduled__2025-09-02T07:35:00+00:00, execution_date=20250902T073500, start_date=20250904T002436, end_date=20250904T002437
[2025-09-04T00:24:37.554+0000] {standard_task_runner.py:110} ERROR - Failed to execute job 43 for task load_dw (Bash command failed. The command returned a non-zero exit code 1.; 675)
[2025-09-04T00:24:37.598+0000] {local_task_job_runner.py:243} INFO - Task exited with return code 1
[2025-09-04T00:24:37.655+0000] {taskinstance.py:3503} INFO - 0 downstream tasks scheduled from follow-on schedule check
[2025-09-04T00:24:37.658+0000] {local_task_job_runner.py:222} INFO - ::endgroup::
[2025-09-04T00:34:23.288+0000] {local_task_job_runner.py:120} INFO - ::group::Pre task execution logs
[2025-09-04T00:34:23.514+0000] {taskinstance.py:2076} INFO - Dependencies all met for dep_context=non-requeueable deps ti=<TaskInstance: banvic_pipeline.load_dw scheduled__2025-09-02T07:35:00+00:00 [queued]>
[2025-09-04T00:34:23.554+0000] {taskinstance.py:2076} INFO - Dependencies all met for dep_context=requeueable deps ti=<TaskInstance: banvic_pipeline.load_dw scheduled__2025-09-02T07:35:00+00:00 [queued]>
[2025-09-04T00:34:23.555+0000] {taskinstance.py:2306} INFO - Starting attempt 1 of 2
[2025-09-04T00:34:23.580+0000] {taskinstance.py:2330} INFO - Executing <Task(BashOperator): load_dw> on 2025-09-02 07:35:00+00:00
[2025-09-04T00:34:23.586+0000] {standard_task_runner.py:64} INFO - Started process 214 to run task
[2025-09-04T00:34:23.590+0000] {standard_task_runner.py:90} INFO - Running: ['airflow', 'tasks', 'run', 'banvic_pipeline', 'load_dw', 'scheduled__2025-09-02T07:35:00+00:00', '--job-id', '48', '--raw', '--subdir', 'DAGS_FOLDER/banvic_pipeline.py', '--cfg-path', '/tmp/tmp_3fajpgm']
[2025-09-04T00:34:23.593+0000] {standard_task_runner.py:91} INFO - Job 48: Subtask load_dw
[2025-09-04T00:34:23.780+0000] {task_command.py:426} INFO - Running <TaskInstance: banvic_pipeline.load_dw scheduled__2025-09-02T07:35:00+00:00 [running]> on host 8ecc11fed1c2
[2025-09-04T00:34:24.040+0000] {taskinstance.py:2648} INFO - Exporting env vars: AIRFLOW_CTX_DAG_OWNER='lucas' AIRFLOW_CTX_DAG_ID='banvic_pipeline' AIRFLOW_CTX_TASK_ID='load_dw' AIRFLOW_CTX_EXECUTION_DATE='2025-09-02T07:35:00+00:00' AIRFLOW_CTX_TRY_NUMBER='1' AIRFLOW_CTX_DAG_RUN_ID='scheduled__2025-09-02T07:35:00+00:00'
[2025-09-04T00:34:24.041+0000] {taskinstance.py:430} INFO - ::endgroup::
[2025-09-04T00:34:24.059+0000] {subprocess.py:63} INFO - Tmp dir root location: /tmp
[2025-09-04T00:34:24.063+0000] {subprocess.py:75} INFO - Running command: ['/usr/bin/bash', '-c', 'cd /opt/airflow/project && python scripts/load_dw.py']
[2025-09-04T00:34:24.072+0000] {subprocess.py:86} INFO - Output:
[2025-09-04T00:34:24.348+0000] {subprocess.py:93} INFO - Traceback (most recent call last):
[2025-09-04T00:34:24.349+0000] {subprocess.py:93} INFO -   File "/opt/airflow/project/scripts/load_dw.py", line 103, in <module>
[2025-09-04T00:34:24.352+0000] {subprocess.py:93} INFO -     main()
[2025-09-04T00:34:24.353+0000] {subprocess.py:93} INFO -   File "/opt/airflow/project/scripts/load_dw.py", line 63, in main
[2025-09-04T00:34:24.356+0000] {subprocess.py:93} INFO -     conn = get_dw_conn()
[2025-09-04T00:34:24.357+0000] {subprocess.py:93} INFO -   File "/opt/airflow/project/scripts/load_dw.py", line 29, in get_dw_conn
[2025-09-04T00:34:24.360+0000] {subprocess.py:93} INFO -     return psycopg2.connect(
[2025-09-04T00:34:24.362+0000] {subprocess.py:93} INFO -   File "/home/airflow/.local/lib/python3.10/site-packages/psycopg2/__init__.py", line 122, in connect
[2025-09-04T00:34:24.363+0000] {subprocess.py:93} INFO -     conn = _connect(dsn, connection_factory=connection_factory, **kwasync)
[2025-09-04T00:34:24.364+0000] {subprocess.py:93} INFO - psycopg2.OperationalError: connection to server at "localhost" (::1), port 56432 failed: Connection refused
[2025-09-04T00:34:24.365+0000] {subprocess.py:93} INFO - 	Is the server running on that host and accepting TCP/IP connections?
[2025-09-04T00:34:24.367+0000] {subprocess.py:93} INFO - connection to server at "localhost" (127.0.0.1), port 56432 failed: Connection refused
[2025-09-04T00:34:24.368+0000] {subprocess.py:93} INFO - 	Is the server running on that host and accepting TCP/IP connections?
[2025-09-04T00:34:24.368+0000] {subprocess.py:93} INFO - 
[2025-09-04T00:34:24.371+0000] {subprocess.py:97} INFO - Command exited with return code 1
[2025-09-04T00:34:24.371+0000] {taskinstance.py:441} INFO - ::group::Post task execution logs
[2025-09-04T00:34:24.421+0000] {taskinstance.py:2905} ERROR - Task failed with exception
Traceback (most recent call last):
  File "/home/airflow/.local/lib/python3.10/site-packages/airflow/models/taskinstance.py", line 465, in _execute_task
    result = _execute_callable(context=context, **execute_callable_kwargs)
  File "/home/airflow/.local/lib/python3.10/site-packages/airflow/models/taskinstance.py", line 432, in _execute_callable
    return execute_callable(context=context, **execute_callable_kwargs)
  File "/home/airflow/.local/lib/python3.10/site-packages/airflow/models/baseoperator.py", line 401, in wrapper
    return func(self, *args, **kwargs)
  File "/home/airflow/.local/lib/python3.10/site-packages/airflow/operators/bash.py", line 243, in execute
    raise AirflowException(
airflow.exceptions.AirflowException: Bash command failed. The command returned a non-zero exit code 1.
[2025-09-04T00:34:24.427+0000] {taskinstance.py:1206} INFO - Marking task as UP_FOR_RETRY. dag_id=banvic_pipeline, task_id=load_dw, run_id=scheduled__2025-09-02T07:35:00+00:00, execution_date=20250902T073500, start_date=20250904T003423, end_date=20250904T003424
[2025-09-04T00:34:24.473+0000] {standard_task_runner.py:110} ERROR - Failed to execute job 48 for task load_dw (Bash command failed. The command returned a non-zero exit code 1.; 214)
[2025-09-04T00:34:24.487+0000] {local_task_job_runner.py:243} INFO - Task exited with return code 1
[2025-09-04T00:34:24.533+0000] {taskinstance.py:3503} INFO - 0 downstream tasks scheduled from follow-on schedule check
[2025-09-04T00:34:24.537+0000] {local_task_job_runner.py:222} INFO - ::endgroup::
